[2019-07-26 10:51:39,862][MainThread:139925943555904][task_id:django.request][exception.py:135][ERROR][Internal Server Error: /login/]
Traceback (most recent call last):
  File "/usr/local/python36/lib/python3.6/site-packages/django/core/handlers/exception.py", line 41, in inner
    response = get_response(request)
  File "/usr/local/python36/lib/python3.6/site-packages/django/core/handlers/base.py", line 187, in _get_response
    response = self.process_exception_by_middleware(e, request)
  File "/usr/local/python36/lib/python3.6/site-packages/django/core/handlers/base.py", line 185, in _get_response
    response = wrapped_callback(request, *callback_args, **callback_kwargs)
  File "/mnt/wwwroot/cms/app01/views.py", line 59, in login
    status = request.session[gt.GT_STATUS_SESSION_KEY]
  File "/usr/local/python36/lib/python3.6/site-packages/django/contrib/sessions/backends/base.py", line 57, in __getitem__
    return self._session[key]
KeyError: 'gt_server_status'
[2019-09-20 14:44:07,884][Thread-4:10460][task_id:django.request][exception.py:135][ERROR][Internal Server Error: /index/]
Traceback (most recent call last):
  File "C:\Program Files\Python36\lib\site-packages\django\core\handlers\exception.py", line 41, in inner
    response = get_response(request)
  File "C:\Program Files\Python36\lib\site-packages\django\core\handlers\base.py", line 187, in _get_response
    response = self.process_exception_by_middleware(e, request)
  File "C:\Program Files\Python36\lib\site-packages\django\core\handlers\base.py", line 185, in _get_response
    response = wrapped_callback(request, *callback_args, **callback_kwargs)
  File "C:\Program Files\Python36\lib\site-packages\django\contrib\auth\decorators.py", line 23, in _wrapped_view
    return view_func(request, *args, **kwargs)
  File "D:\django_test\cms\app01\views.py", line 142, in index
    return JsonResponse(ret)
  File "C:\Program Files\Python36\lib\site-packages\django\http\response.py", line 530, in __init__
    data = json.dumps(data, cls=encoder, **json_dumps_params)
  File "C:\Program Files\Python36\lib\json\__init__.py", line 238, in dumps
    **kw).encode(obj)
  File "C:\Program Files\Python36\lib\json\encoder.py", line 199, in encode
    chunks = self.iterencode(o, _one_shot=True)
  File "C:\Program Files\Python36\lib\json\encoder.py", line 257, in iterencode
    return _iterencode(o, 0)
  File "C:\Program Files\Python36\lib\site-packages\django\core\serializers\json.py", line 124, in default
    return super(DjangoJSONEncoder, self).default(o)
  File "C:\Program Files\Python36\lib\json\encoder.py", line 180, in default
    o.__class__.__name__)
TypeError: Object of type 'TypeError' is not JSON serializable
[2019-09-20 14:46:09,325][Thread-5:6160][task_id:django.request][exception.py:135][ERROR][Internal Server Error: /index/]
Traceback (most recent call last):
  File "C:\Program Files\Python36\lib\site-packages\django\core\handlers\exception.py", line 41, in inner
    response = get_response(request)
  File "C:\Program Files\Python36\lib\site-packages\django\core\handlers\base.py", line 187, in _get_response
    response = self.process_exception_by_middleware(e, request)
  File "C:\Program Files\Python36\lib\site-packages\django\core\handlers\base.py", line 185, in _get_response
    response = wrapped_callback(request, *callback_args, **callback_kwargs)
  File "C:\Program Files\Python36\lib\site-packages\django\contrib\auth\decorators.py", line 23, in _wrapped_view
    return view_func(request, *args, **kwargs)
  File "D:\django_test\cms\app01\views.py", line 143, in index
    return JsonResponse(ret)
  File "C:\Program Files\Python36\lib\site-packages\django\http\response.py", line 530, in __init__
    data = json.dumps(data, cls=encoder, **json_dumps_params)
  File "C:\Program Files\Python36\lib\json\__init__.py", line 238, in dumps
    **kw).encode(obj)
  File "C:\Program Files\Python36\lib\json\encoder.py", line 199, in encode
    chunks = self.iterencode(o, _one_shot=True)
  File "C:\Program Files\Python36\lib\json\encoder.py", line 257, in iterencode
    return _iterencode(o, 0)
  File "C:\Program Files\Python36\lib\site-packages\django\core\serializers\json.py", line 124, in default
    return super(DjangoJSONEncoder, self).default(o)
  File "C:\Program Files\Python36\lib\json\encoder.py", line 180, in default
    o.__class__.__name__)
TypeError: Object of type 'TypeError' is not JSON serializable
[2019-09-20 14:48:07,768][Thread-4:4192][task_id:django.request][exception.py:135][ERROR][Internal Server Error: /index/]
Traceback (most recent call last):
  File "C:\Program Files\Python36\lib\site-packages\django\core\handlers\exception.py", line 41, in inner
    response = get_response(request)
  File "C:\Program Files\Python36\lib\site-packages\django\core\handlers\base.py", line 187, in _get_response
    response = self.process_exception_by_middleware(e, request)
  File "C:\Program Files\Python36\lib\site-packages\django\core\handlers\base.py", line 185, in _get_response
    response = wrapped_callback(request, *callback_args, **callback_kwargs)
  File "C:\Program Files\Python36\lib\site-packages\django\contrib\auth\decorators.py", line 23, in _wrapped_view
    return view_func(request, *args, **kwargs)
  File "D:\django_test\cms\app01\views.py", line 144, in index
    return JsonResponse(ret)
  File "C:\Program Files\Python36\lib\site-packages\django\http\response.py", line 530, in __init__
    data = json.dumps(data, cls=encoder, **json_dumps_params)
  File "C:\Program Files\Python36\lib\json\__init__.py", line 238, in dumps
    **kw).encode(obj)
  File "C:\Program Files\Python36\lib\json\encoder.py", line 199, in encode
    chunks = self.iterencode(o, _one_shot=True)
  File "C:\Program Files\Python36\lib\json\encoder.py", line 257, in iterencode
    return _iterencode(o, 0)
  File "C:\Program Files\Python36\lib\site-packages\django\core\serializers\json.py", line 124, in default
    return super(DjangoJSONEncoder, self).default(o)
  File "C:\Program Files\Python36\lib\json\encoder.py", line 180, in default
    o.__class__.__name__)
TypeError: Object of type 'TypeError' is not JSON serializable
[2019-09-20 14:51:30,198][Thread-4:9080][task_id:django.request][exception.py:135][ERROR][Internal Server Error: /index/]
Traceback (most recent call last):
  File "C:\Program Files\Python36\lib\site-packages\django\core\handlers\exception.py", line 41, in inner
    response = get_response(request)
  File "C:\Program Files\Python36\lib\site-packages\django\core\handlers\base.py", line 187, in _get_response
    response = self.process_exception_by_middleware(e, request)
  File "C:\Program Files\Python36\lib\site-packages\django\core\handlers\base.py", line 185, in _get_response
    response = wrapped_callback(request, *callback_args, **callback_kwargs)
  File "C:\Program Files\Python36\lib\site-packages\django\contrib\auth\decorators.py", line 23, in _wrapped_view
    return view_func(request, *args, **kwargs)
  File "D:\django_test\cms\app01\views.py", line 146, in index
    return JsonResponse(ret)
  File "C:\Program Files\Python36\lib\site-packages\django\http\response.py", line 530, in __init__
    data = json.dumps(data, cls=encoder, **json_dumps_params)
  File "C:\Program Files\Python36\lib\json\__init__.py", line 238, in dumps
    **kw).encode(obj)
  File "C:\Program Files\Python36\lib\json\encoder.py", line 199, in encode
    chunks = self.iterencode(o, _one_shot=True)
  File "C:\Program Files\Python36\lib\json\encoder.py", line 257, in iterencode
    return _iterencode(o, 0)
  File "C:\Program Files\Python36\lib\site-packages\django\core\serializers\json.py", line 124, in default
    return super(DjangoJSONEncoder, self).default(o)
  File "C:\Program Files\Python36\lib\json\encoder.py", line 180, in default
    o.__class__.__name__)
TypeError: Object of type 'TypeError' is not JSON serializable
[2019-09-20 14:53:08,571][Thread-4:10648][task_id:django.request][exception.py:135][ERROR][Internal Server Error: /index/]
Traceback (most recent call last):
  File "C:\Program Files\Python36\lib\site-packages\django\core\handlers\exception.py", line 41, in inner
    response = get_response(request)
  File "C:\Program Files\Python36\lib\site-packages\django\core\handlers\base.py", line 187, in _get_response
    response = self.process_exception_by_middleware(e, request)
  File "C:\Program Files\Python36\lib\site-packages\django\core\handlers\base.py", line 185, in _get_response
    response = wrapped_callback(request, *callback_args, **callback_kwargs)
  File "C:\Program Files\Python36\lib\site-packages\django\contrib\auth\decorators.py", line 23, in _wrapped_view
    return view_func(request, *args, **kwargs)
  File "D:\django_test\cms\app01\views.py", line 144, in index
    return JsonResponse(ret)
  File "C:\Program Files\Python36\lib\site-packages\django\http\response.py", line 530, in __init__
    data = json.dumps(data, cls=encoder, **json_dumps_params)
  File "C:\Program Files\Python36\lib\json\__init__.py", line 238, in dumps
    **kw).encode(obj)
  File "C:\Program Files\Python36\lib\json\encoder.py", line 199, in encode
    chunks = self.iterencode(o, _one_shot=True)
  File "C:\Program Files\Python36\lib\json\encoder.py", line 257, in iterencode
    return _iterencode(o, 0)
  File "C:\Program Files\Python36\lib\site-packages\django\core\serializers\json.py", line 124, in default
    return super(DjangoJSONEncoder, self).default(o)
  File "C:\Program Files\Python36\lib\json\encoder.py", line 180, in default
    o.__class__.__name__)
TypeError: Object of type 'TypeError' is not JSON serializable
[2019-09-20 14:54:07,113][Thread-4:3380][task_id:django.request][exception.py:135][ERROR][Internal Server Error: /index/]
Traceback (most recent call last):
  File "C:\Program Files\Python36\lib\site-packages\django\core\handlers\exception.py", line 41, in inner
    response = get_response(request)
  File "C:\Program Files\Python36\lib\site-packages\django\core\handlers\base.py", line 187, in _get_response
    response = self.process_exception_by_middleware(e, request)
  File "C:\Program Files\Python36\lib\site-packages\django\core\handlers\base.py", line 185, in _get_response
    response = wrapped_callback(request, *callback_args, **callback_kwargs)
  File "C:\Program Files\Python36\lib\site-packages\django\contrib\auth\decorators.py", line 23, in _wrapped_view
    return view_func(request, *args, **kwargs)
  File "D:\django_test\cms\app01\views.py", line 145, in index
    return JsonResponse(ret)
  File "C:\Program Files\Python36\lib\site-packages\django\http\response.py", line 530, in __init__
    data = json.dumps(data, cls=encoder, **json_dumps_params)
  File "C:\Program Files\Python36\lib\json\__init__.py", line 238, in dumps
    **kw).encode(obj)
  File "C:\Program Files\Python36\lib\json\encoder.py", line 199, in encode
    chunks = self.iterencode(o, _one_shot=True)
  File "C:\Program Files\Python36\lib\json\encoder.py", line 257, in iterencode
    return _iterencode(o, 0)
  File "C:\Program Files\Python36\lib\site-packages\django\core\serializers\json.py", line 124, in default
    return super(DjangoJSONEncoder, self).default(o)
  File "C:\Program Files\Python36\lib\json\encoder.py", line 180, in default
    o.__class__.__name__)
TypeError: Object of type 'TypeError' is not JSON serializable
[2019-09-20 14:59:19,129][Thread-4:11476][task_id:django.request][exception.py:135][ERROR][Internal Server Error: /index/]
Traceback (most recent call last):
  File "C:\Program Files\Python36\lib\site-packages\django\core\handlers\exception.py", line 41, in inner
    response = get_response(request)
  File "C:\Program Files\Python36\lib\site-packages\django\core\handlers\base.py", line 187, in _get_response
    response = self.process_exception_by_middleware(e, request)
  File "C:\Program Files\Python36\lib\site-packages\django\core\handlers\base.py", line 185, in _get_response
    response = wrapped_callback(request, *callback_args, **callback_kwargs)
  File "C:\Program Files\Python36\lib\site-packages\django\contrib\auth\decorators.py", line 23, in _wrapped_view
    return view_func(request, *args, **kwargs)
  File "D:\django_test\cms\app01\views.py", line 145, in index
    return JsonResponse(ret)
  File "C:\Program Files\Python36\lib\site-packages\django\http\response.py", line 530, in __init__
    data = json.dumps(data, cls=encoder, **json_dumps_params)
  File "C:\Program Files\Python36\lib\json\__init__.py", line 238, in dumps
    **kw).encode(obj)
  File "C:\Program Files\Python36\lib\json\encoder.py", line 199, in encode
    chunks = self.iterencode(o, _one_shot=True)
  File "C:\Program Files\Python36\lib\json\encoder.py", line 257, in iterencode
    return _iterencode(o, 0)
  File "C:\Program Files\Python36\lib\site-packages\django\core\serializers\json.py", line 124, in default
    return super(DjangoJSONEncoder, self).default(o)
  File "C:\Program Files\Python36\lib\json\encoder.py", line 180, in default
    o.__class__.__name__)
TypeError: Object of type 'TypeError' is not JSON serializable
[2019-09-20 15:01:15,397][Thread-5:3152][task_id:django.request][exception.py:135][ERROR][Internal Server Error: /index/]
Traceback (most recent call last):
  File "C:\Program Files\Python36\lib\site-packages\django\core\handlers\exception.py", line 41, in inner
    response = get_response(request)
  File "C:\Program Files\Python36\lib\site-packages\django\core\handlers\base.py", line 187, in _get_response
    response = self.process_exception_by_middleware(e, request)
  File "C:\Program Files\Python36\lib\site-packages\django\core\handlers\base.py", line 185, in _get_response
    response = wrapped_callback(request, *callback_args, **callback_kwargs)
  File "C:\Program Files\Python36\lib\site-packages\django\contrib\auth\decorators.py", line 23, in _wrapped_view
    return view_func(request, *args, **kwargs)
  File "D:\django_test\cms\app01\views.py", line 145, in index
    return JsonResponse(ret)
  File "C:\Program Files\Python36\lib\site-packages\django\http\response.py", line 530, in __init__
    data = json.dumps(data, cls=encoder, **json_dumps_params)
  File "C:\Program Files\Python36\lib\json\__init__.py", line 238, in dumps
    **kw).encode(obj)
  File "C:\Program Files\Python36\lib\json\encoder.py", line 199, in encode
    chunks = self.iterencode(o, _one_shot=True)
  File "C:\Program Files\Python36\lib\json\encoder.py", line 257, in iterencode
    return _iterencode(o, 0)
  File "C:\Program Files\Python36\lib\site-packages\django\core\serializers\json.py", line 124, in default
    return super(DjangoJSONEncoder, self).default(o)
  File "C:\Program Files\Python36\lib\json\encoder.py", line 180, in default
    o.__class__.__name__)
TypeError: Object of type 'TypeError' is not JSON serializable
[2019-09-20 15:03:04,536][Thread-4:11336][task_id:django.request][exception.py:135][ERROR][Internal Server Error: /index/]
Traceback (most recent call last):
  File "C:\Program Files\Python36\lib\site-packages\django\core\handlers\exception.py", line 41, in inner
    response = get_response(request)
  File "C:\Program Files\Python36\lib\site-packages\django\core\handlers\base.py", line 187, in _get_response
    response = self.process_exception_by_middleware(e, request)
  File "C:\Program Files\Python36\lib\site-packages\django\core\handlers\base.py", line 185, in _get_response
    response = wrapped_callback(request, *callback_args, **callback_kwargs)
  File "C:\Program Files\Python36\lib\site-packages\django\contrib\auth\decorators.py", line 23, in _wrapped_view
    return view_func(request, *args, **kwargs)
  File "D:\django_test\cms\app01\views.py", line 145, in index
    return JsonResponse(ret)
  File "C:\Program Files\Python36\lib\site-packages\django\http\response.py", line 530, in __init__
    data = json.dumps(data, cls=encoder, **json_dumps_params)
  File "C:\Program Files\Python36\lib\json\__init__.py", line 238, in dumps
    **kw).encode(obj)
  File "C:\Program Files\Python36\lib\json\encoder.py", line 199, in encode
    chunks = self.iterencode(o, _one_shot=True)
  File "C:\Program Files\Python36\lib\json\encoder.py", line 257, in iterencode
    return _iterencode(o, 0)
  File "C:\Program Files\Python36\lib\site-packages\django\core\serializers\json.py", line 124, in default
    return super(DjangoJSONEncoder, self).default(o)
  File "C:\Program Files\Python36\lib\json\encoder.py", line 180, in default
    o.__class__.__name__)
TypeError: Object of type 'TypeError' is not JSON serializable
[2019-09-20 15:05:07,536][Thread-4:11804][task_id:django.request][exception.py:135][ERROR][Internal Server Error: /index/]
Traceback (most recent call last):
  File "C:\Program Files\Python36\lib\site-packages\django\core\handlers\exception.py", line 41, in inner
    response = get_response(request)
  File "C:\Program Files\Python36\lib\site-packages\django\core\handlers\base.py", line 187, in _get_response
    response = self.process_exception_by_middleware(e, request)
  File "C:\Program Files\Python36\lib\site-packages\django\core\handlers\base.py", line 185, in _get_response
    response = wrapped_callback(request, *callback_args, **callback_kwargs)
  File "C:\Program Files\Python36\lib\site-packages\django\contrib\auth\decorators.py", line 23, in _wrapped_view
    return view_func(request, *args, **kwargs)
  File "D:\django_test\cms\app01\views.py", line 145, in index
    return JsonResponse(ret)
  File "C:\Program Files\Python36\lib\site-packages\django\http\response.py", line 530, in __init__
    data = json.dumps(data, cls=encoder, **json_dumps_params)
  File "C:\Program Files\Python36\lib\json\__init__.py", line 238, in dumps
    **kw).encode(obj)
  File "C:\Program Files\Python36\lib\json\encoder.py", line 199, in encode
    chunks = self.iterencode(o, _one_shot=True)
  File "C:\Program Files\Python36\lib\json\encoder.py", line 257, in iterencode
    return _iterencode(o, 0)
  File "C:\Program Files\Python36\lib\site-packages\django\core\serializers\json.py", line 124, in default
    return super(DjangoJSONEncoder, self).default(o)
  File "C:\Program Files\Python36\lib\json\encoder.py", line 180, in default
    o.__class__.__name__)
TypeError: Object of type 'TypeError' is not JSON serializable
[2019-09-20 15:12:26,958][Thread-4:6760][task_id:django.request][exception.py:135][ERROR][Internal Server Error: /index/]
Traceback (most recent call last):
  File "C:\Program Files\Python36\lib\site-packages\django\core\handlers\exception.py", line 41, in inner
    response = get_response(request)
  File "C:\Program Files\Python36\lib\site-packages\django\core\handlers\base.py", line 187, in _get_response
    response = self.process_exception_by_middleware(e, request)
  File "C:\Program Files\Python36\lib\site-packages\django\core\handlers\base.py", line 185, in _get_response
    response = wrapped_callback(request, *callback_args, **callback_kwargs)
  File "C:\Program Files\Python36\lib\site-packages\django\contrib\auth\decorators.py", line 23, in _wrapped_view
    return view_func(request, *args, **kwargs)
  File "D:\django_test\cms\app01\views.py", line 145, in index
    return JsonResponse(ret)
  File "C:\Program Files\Python36\lib\site-packages\django\http\response.py", line 530, in __init__
    data = json.dumps(data, cls=encoder, **json_dumps_params)
  File "C:\Program Files\Python36\lib\json\__init__.py", line 238, in dumps
    **kw).encode(obj)
  File "C:\Program Files\Python36\lib\json\encoder.py", line 199, in encode
    chunks = self.iterencode(o, _one_shot=True)
  File "C:\Program Files\Python36\lib\json\encoder.py", line 257, in iterencode
    return _iterencode(o, 0)
  File "C:\Program Files\Python36\lib\site-packages\django\core\serializers\json.py", line 124, in default
    return super(DjangoJSONEncoder, self).default(o)
  File "C:\Program Files\Python36\lib\json\encoder.py", line 180, in default
    o.__class__.__name__)
TypeError: Object of type 'TypeError' is not JSON serializable
[2019-09-20 15:14:25,883][Thread-4:10824][task_id:django.request][exception.py:135][ERROR][Internal Server Error: /index/]
Traceback (most recent call last):
  File "C:\Program Files\Python36\lib\site-packages\django\core\handlers\exception.py", line 41, in inner
    response = get_response(request)
  File "C:\Program Files\Python36\lib\site-packages\django\core\handlers\base.py", line 187, in _get_response
    response = self.process_exception_by_middleware(e, request)
  File "C:\Program Files\Python36\lib\site-packages\django\core\handlers\base.py", line 185, in _get_response
    response = wrapped_callback(request, *callback_args, **callback_kwargs)
  File "C:\Program Files\Python36\lib\site-packages\django\contrib\auth\decorators.py", line 23, in _wrapped_view
    return view_func(request, *args, **kwargs)
  File "D:\django_test\cms\app01\views.py", line 145, in index
    return JsonResponse(ret)
  File "C:\Program Files\Python36\lib\site-packages\django\http\response.py", line 530, in __init__
    data = json.dumps(data, cls=encoder, **json_dumps_params)
  File "C:\Program Files\Python36\lib\json\__init__.py", line 238, in dumps
    **kw).encode(obj)
  File "C:\Program Files\Python36\lib\json\encoder.py", line 199, in encode
    chunks = self.iterencode(o, _one_shot=True)
  File "C:\Program Files\Python36\lib\json\encoder.py", line 257, in iterencode
    return _iterencode(o, 0)
  File "C:\Program Files\Python36\lib\site-packages\django\core\serializers\json.py", line 124, in default
    return super(DjangoJSONEncoder, self).default(o)
  File "C:\Program Files\Python36\lib\json\encoder.py", line 180, in default
    o.__class__.__name__)
TypeError: Object of type 'TypeError' is not JSON serializable
[2019-09-20 15:17:51,025][Thread-9:7296][task_id:django.request][exception.py:135][ERROR][Internal Server Error: /index/]
Traceback (most recent call last):
  File "C:\Program Files\Python36\lib\site-packages\django\core\handlers\exception.py", line 41, in inner
    response = get_response(request)
  File "C:\Program Files\Python36\lib\site-packages\django\core\handlers\base.py", line 187, in _get_response
    response = self.process_exception_by_middleware(e, request)
  File "C:\Program Files\Python36\lib\site-packages\django\core\handlers\base.py", line 185, in _get_response
    response = wrapped_callback(request, *callback_args, **callback_kwargs)
  File "C:\Program Files\Python36\lib\site-packages\django\contrib\auth\decorators.py", line 23, in _wrapped_view
    return view_func(request, *args, **kwargs)
  File "D:\django_test\cms\app01\views.py", line 145, in index
    return JsonResponse(ret)
  File "C:\Program Files\Python36\lib\site-packages\django\http\response.py", line 530, in __init__
    data = json.dumps(data, cls=encoder, **json_dumps_params)
  File "C:\Program Files\Python36\lib\json\__init__.py", line 238, in dumps
    **kw).encode(obj)
  File "C:\Program Files\Python36\lib\json\encoder.py", line 199, in encode
    chunks = self.iterencode(o, _one_shot=True)
  File "C:\Program Files\Python36\lib\json\encoder.py", line 257, in iterencode
    return _iterencode(o, 0)
  File "C:\Program Files\Python36\lib\site-packages\django\core\serializers\json.py", line 124, in default
    return super(DjangoJSONEncoder, self).default(o)
  File "C:\Program Files\Python36\lib\json\encoder.py", line 180, in default
    o.__class__.__name__)
TypeError: Object of type 'TypeError' is not JSON serializable
[2019-09-20 15:22:59,960][Thread-9:5256][task_id:django.request][exception.py:135][ERROR][Internal Server Error: /index/]
Traceback (most recent call last):
  File "C:\Program Files\Python36\lib\site-packages\django\core\handlers\exception.py", line 41, in inner
    response = get_response(request)
  File "C:\Program Files\Python36\lib\site-packages\django\core\handlers\base.py", line 187, in _get_response
    response = self.process_exception_by_middleware(e, request)
  File "C:\Program Files\Python36\lib\site-packages\django\core\handlers\base.py", line 185, in _get_response
    response = wrapped_callback(request, *callback_args, **callback_kwargs)
  File "C:\Program Files\Python36\lib\site-packages\django\contrib\auth\decorators.py", line 23, in _wrapped_view
    return view_func(request, *args, **kwargs)
  File "D:\django_test\cms\app01\views.py", line 145, in index
    return JsonResponse(ret)
  File "C:\Program Files\Python36\lib\site-packages\django\http\response.py", line 530, in __init__
    data = json.dumps(data, cls=encoder, **json_dumps_params)
  File "C:\Program Files\Python36\lib\json\__init__.py", line 238, in dumps
    **kw).encode(obj)
  File "C:\Program Files\Python36\lib\json\encoder.py", line 199, in encode
    chunks = self.iterencode(o, _one_shot=True)
  File "C:\Program Files\Python36\lib\json\encoder.py", line 257, in iterencode
    return _iterencode(o, 0)
  File "C:\Program Files\Python36\lib\site-packages\django\core\serializers\json.py", line 124, in default
    return super(DjangoJSONEncoder, self).default(o)
  File "C:\Program Files\Python36\lib\json\encoder.py", line 180, in default
    o.__class__.__name__)
TypeError: Object of type 'TypeError' is not JSON serializable
[2019-09-20 15:31:11,403][Thread-8:13012][task_id:django.request][exception.py:135][ERROR][Internal Server Error: /index/]
Traceback (most recent call last):
  File "C:\Program Files\Python36\lib\site-packages\django\core\handlers\exception.py", line 41, in inner
    response = get_response(request)
  File "C:\Program Files\Python36\lib\site-packages\django\core\handlers\base.py", line 187, in _get_response
    response = self.process_exception_by_middleware(e, request)
  File "C:\Program Files\Python36\lib\site-packages\django\core\handlers\base.py", line 185, in _get_response
    response = wrapped_callback(request, *callback_args, **callback_kwargs)
  File "C:\Program Files\Python36\lib\site-packages\django\contrib\auth\decorators.py", line 23, in _wrapped_view
    return view_func(request, *args, **kwargs)
  File "D:\django_test\cms\app01\views.py", line 102, in index
    filename = file_obj.name
AttributeError: 'NoneType' object has no attribute 'name'
[2019-09-20 15:31:11,423][Thread-7:13032][task_id:django.request][exception.py:135][ERROR][Internal Server Error: /index/]
Traceback (most recent call last):
  File "C:\Program Files\Python36\lib\site-packages\django\core\handlers\exception.py", line 41, in inner
    response = get_response(request)
  File "C:\Program Files\Python36\lib\site-packages\django\core\handlers\base.py", line 187, in _get_response
    response = self.process_exception_by_middleware(e, request)
  File "C:\Program Files\Python36\lib\site-packages\django\core\handlers\base.py", line 185, in _get_response
    response = wrapped_callback(request, *callback_args, **callback_kwargs)
  File "C:\Program Files\Python36\lib\site-packages\django\contrib\auth\decorators.py", line 23, in _wrapped_view
    return view_func(request, *args, **kwargs)
  File "D:\django_test\cms\app01\views.py", line 102, in index
    filename = file_obj.name
AttributeError: 'NoneType' object has no attribute 'name'
[2019-09-20 15:35:12,478][Thread-4:12252][task_id:django.request][exception.py:135][ERROR][Internal Server Error: /index/]
Traceback (most recent call last):
  File "C:\Program Files\Python36\lib\site-packages\django\core\handlers\exception.py", line 41, in inner
    response = get_response(request)
  File "C:\Program Files\Python36\lib\site-packages\django\core\handlers\base.py", line 187, in _get_response
    response = self.process_exception_by_middleware(e, request)
  File "C:\Program Files\Python36\lib\site-packages\django\core\handlers\base.py", line 185, in _get_response
    response = wrapped_callback(request, *callback_args, **callback_kwargs)
  File "C:\Program Files\Python36\lib\site-packages\django\contrib\auth\decorators.py", line 23, in _wrapped_view
    return view_func(request, *args, **kwargs)
  File "D:\django_test\cms\app01\views.py", line 146, in index
    return JsonResponse(ret)
  File "C:\Program Files\Python36\lib\site-packages\django\http\response.py", line 530, in __init__
    data = json.dumps(data, cls=encoder, **json_dumps_params)
  File "C:\Program Files\Python36\lib\json\__init__.py", line 238, in dumps
    **kw).encode(obj)
  File "C:\Program Files\Python36\lib\json\encoder.py", line 199, in encode
    chunks = self.iterencode(o, _one_shot=True)
  File "C:\Program Files\Python36\lib\json\encoder.py", line 257, in iterencode
    return _iterencode(o, 0)
  File "C:\Program Files\Python36\lib\site-packages\django\core\serializers\json.py", line 124, in default
    return super(DjangoJSONEncoder, self).default(o)
  File "C:\Program Files\Python36\lib\json\encoder.py", line 180, in default
    o.__class__.__name__)
TypeError: Object of type 'TypeError' is not JSON serializable
[2019-09-20 15:37:21,037][Thread-4:7580][task_id:django.request][exception.py:135][ERROR][Internal Server Error: /index/]
Traceback (most recent call last):
  File "C:\Program Files\Python36\lib\site-packages\django\core\handlers\exception.py", line 41, in inner
    response = get_response(request)
  File "C:\Program Files\Python36\lib\site-packages\django\core\handlers\base.py", line 187, in _get_response
    response = self.process_exception_by_middleware(e, request)
  File "C:\Program Files\Python36\lib\site-packages\django\core\handlers\base.py", line 185, in _get_response
    response = wrapped_callback(request, *callback_args, **callback_kwargs)
  File "C:\Program Files\Python36\lib\site-packages\django\contrib\auth\decorators.py", line 23, in _wrapped_view
    return view_func(request, *args, **kwargs)
  File "D:\django_test\cms\app01\views.py", line 147, in index
    return JsonResponse(ret)
  File "C:\Program Files\Python36\lib\site-packages\django\http\response.py", line 530, in __init__
    data = json.dumps(data, cls=encoder, **json_dumps_params)
  File "C:\Program Files\Python36\lib\json\__init__.py", line 238, in dumps
    **kw).encode(obj)
  File "C:\Program Files\Python36\lib\json\encoder.py", line 199, in encode
    chunks = self.iterencode(o, _one_shot=True)
  File "C:\Program Files\Python36\lib\json\encoder.py", line 257, in iterencode
    return _iterencode(o, 0)
  File "C:\Program Files\Python36\lib\site-packages\django\core\serializers\json.py", line 124, in default
    return super(DjangoJSONEncoder, self).default(o)
  File "C:\Program Files\Python36\lib\json\encoder.py", line 180, in default
    o.__class__.__name__)
TypeError: Object of type 'TypeError' is not JSON serializable
[2019-09-20 15:40:08,572][Thread-4:10764][task_id:django.request][exception.py:135][ERROR][Internal Server Error: /index/]
Traceback (most recent call last):
  File "C:\Program Files\Python36\lib\site-packages\django\core\handlers\exception.py", line 41, in inner
    response = get_response(request)
  File "C:\Program Files\Python36\lib\site-packages\django\core\handlers\base.py", line 187, in _get_response
    response = self.process_exception_by_middleware(e, request)
  File "C:\Program Files\Python36\lib\site-packages\django\core\handlers\base.py", line 185, in _get_response
    response = wrapped_callback(request, *callback_args, **callback_kwargs)
  File "C:\Program Files\Python36\lib\site-packages\django\contrib\auth\decorators.py", line 23, in _wrapped_view
    return view_func(request, *args, **kwargs)
  File "D:\django_test\cms\app01\views.py", line 148, in index
    return JsonResponse(ret)
  File "C:\Program Files\Python36\lib\site-packages\django\http\response.py", line 530, in __init__
    data = json.dumps(data, cls=encoder, **json_dumps_params)
  File "C:\Program Files\Python36\lib\json\__init__.py", line 238, in dumps
    **kw).encode(obj)
  File "C:\Program Files\Python36\lib\json\encoder.py", line 199, in encode
    chunks = self.iterencode(o, _one_shot=True)
  File "C:\Program Files\Python36\lib\json\encoder.py", line 257, in iterencode
    return _iterencode(o, 0)
  File "C:\Program Files\Python36\lib\site-packages\django\core\serializers\json.py", line 124, in default
    return super(DjangoJSONEncoder, self).default(o)
  File "C:\Program Files\Python36\lib\json\encoder.py", line 180, in default
    o.__class__.__name__)
TypeError: Object of type 'TypeError' is not JSON serializable
